Workbook

Sheet GDP_Current%
A2: Gross Domestic Product At Current Basic Prices (=N=Million) | B2: 2019 | C2: 2020 | D2: 2021 | E2: 2022 | F2: 2023 | G2: 2024
A4: AGRICULTURE
A5: 1. Crop Production | B5: 35925189 | C5: 41220372 | D5: 48305044 | E5: 50186279 | F5: 56895936 | G5: 61916574
A6: 2. Livestock | B6: 11761132 | C6: 13695440 | D6: 16999300 | E6: 20859132 | F6: 21636501 | G6: 24798474
A7: 3. Forestry | B7: 2695042.6 | C7: 2959350 | D7: 3428890.4 | E7: 4255270.2 | F7: 4857350.1 | G7: 5282876.4
A8: 4. Fishing | B8: 2398510.4 | C8: 2680966.1 | D8: 2769224.1 | E8: 2997299.8 | F8: 3652185.9 | G8: 4463771.8
A9: MINING AND QUARRYING
A10: 5. Crude Petroleum and Natural Gas | B10: 11952450 | C10: 10195626 | D10: 9636017.9 | E10: 11972758 | F10: 13106152 | G10: 14601246
A11: 6. Coal Mining | B11: 22818.997 | C11: 20815.019 | D11: 22002.008 | E11: 23065.549 | F11: 24619.389 | G11: 24357.131
A12: 7. Metal Ores | B12: 39131.433 | C12: 13819.603 | D12: 79290.391 | E12: 117744.49 | F12: 188504.97 | G12: 366581.3
A13: 8. Quarrying and Other Minerals | B13: 388037.89 | C13: 436862.8 | D13: 469766.06 | E13: 531232.59 | F13: 581341.32 | G13: 469135.64
A14: MANUFACTURING | B14: 0 | C14: 0 | D14: 0 | E14: 0 | F14: 0
A15: 9. Oil Refining | B15: 140683.08 | C15: 55858.828 | D15: 31669.185 | E15: 19853.82 | F15: 14761.149 | G15: 11804.435
A16: 10. Cement | B16: 2240142.5 | C16: 2282769.9 | D16: 2527793.2 | E16: 2970251 | F16: 3592985.3 | G16: 4222387.5
A17: 11. Food, Beverage and Tobacco | B17: 6608293.7 | C17: 6053521.1 | D17: 6580710.5 | E17: 7492828.6 | F17: 8988827.2 | G17: 10638413
A18: 12. Textile, Apparel and Footwear | B18: 4372750.4 | C18: 3940591.3 | D18: 6154258.9 | E18: 7329359.5 | F18: 8503356 | G18: 8148223.6
A19: 13. Wood and Wood Products | B19: 570616.78 | C19: 592798.86 | D19: 829248.52 | E19: 1061543.7 | F19: 1173177.1 | G19: 1344300.9
A20: 14. Pulp, Paper and Paper Products | B20: 312806.96 | C20: 270003.4 | D20: 405180.06 | E20: 417153.24 | F20: 462910.02 | G20: 527799.26
A21: 15. Chemical and Pharmaceutical Products | B21: 729119.12 | C21: 851274.7 | D21: 969034.81 | E21: 1213079.2 | F21: 1492798.9 | G21: 1812930.2
A22: 16. Non-Metallic Products | B22: 1090130.8 | C22: 1060937 | D22: 1226589.9 | E22: 1398177.2 | F22: 1543590.8 | G22: 1772171.6
A23: 17. Plastic and Rubber products | B23: 669945.5 | C23: 644346.47 | D23: 716105.52 | E23: 857873.02 | F23: 769186.52 | G23: 892545.42
A24: 18. Electrical and Electronics | B24: 21003.432 | C24: 20389.535 | D24: 42971.226 | E24: 56907.809 | F24: 61861.229 | G24: 66965.693
A25: 19. Basic metal , Iron and Steel | B25: 533391.04 | C25: 510762.82 | D25: 699295.97 | E25: 731562.47 | F25: 816665.86 | G25: 924240.42
A26: 20. Motor vehicles & assembly | B26: 225490.03 | C26: 139620.16 | D26: 251341.07 | E26: 286991.49 | F26: 327635.5 | G26: 368404.23
... A32: 26. ACCOMMODATION AND FOOD SERVICES | B32: 2036922.8 | C32: 1910400.4 | D32: 1632103.7 | E32: 1986152.5 | F32: 2240006.8 | G32: 2606177.9
A33: TRANSPORTATION AND STORAGE | B33: 0 | C33: 0 | D33: 0 | E33: 0 | F33: 0
A34: 27. Road Transport | B34: 3169876.4 | C34: 1827113 | D34: 1827820.4 | E34: 1936808.2 | F34: 2183502.8 | G34: 2947233.4
A35: 28. Rail Transport & Pipelines | B35: 357.17351 | C35: 356.44373 | D35: 365.90838 | E35: 428.41853 | F35: 500.36533 | G35: 970.60756
A36: 29. Water Transport | B36: 148493.55 | C36: 122260.97 | D36: 131396.78 | E36: 153456.9 | F36: 168302.38 | G36: 227868.57
A37: 30. Air Transport | B37: 222466.41 | C37: 101142.97 | D37: 145542.84 | E37: 178470.48 | F37: 215606.45 | G37: 258990.13
A38: 31. Transport Services | B38: 320666.72 | C38: 59829.299 | D38: 58624.315 | E38: 69541.122 | F38: 83330.571 | G38: 99713.67
A39: 32. Post and Courier Services | B39: 44270.416 | C39: 58314.401 | D39: 106273.13 | E39: 155456.78 | F39: 208518.63 | G39: 246282.56
A40: INFORMATION AND COMMUNICATION | B40: 0 | C40: 0 | D40: 0 | E40: 0 | F40: 0
A41: 33. Telecommunications | B41: 13852943 | C41: 16853443 | D41: 18722340 | E41: 20829116 | F41: 23027076 | G41: 25470009
A42: 34. Publishing, | B42: 47313.331 | C42: 41279.72 | D42: 41046.263 | E42: 40672.348 | F42: 51065.681 | G42: 53794.438
A43: 34. Motion Pictures, Sound recording and Music production | B43: 1324243.1 | C43: 1295423.8 | D43: 1681028.5 | E43: 1828933 | F43: 2224361.8 | G43: 2700162.7
A44: 36. Broadcasting | B44: 2221653.8 | C44: 2634046.6 | D44: 2696202.8 | E44: 2867173.1 | F44: 3443492.9 | G44: 4167387.6
A45: 37.ARTS, ENTERTAINMENT AND RECREATION | B45: 1172104.7 | C45: 865734.1 | D45: 927115.81 | E45: 1188715.2 | F45: 1463438.1 | G45: 1788264.1
A46: FINANCIAL AND INSURANCE | B46: 0 | C46: 0 | D46: 0 | E46: 0 | F46: 0
A47: 38. Financial Institutions | B47: 4445513.6 | C47: 5197387.4 | D47: 5671707.9 | E47: 6115979.1 | F47: 7393943.5 | G47: 9091608.3
...

Sheet Nominal GDP growth rate%
A2: Growth Rate of Gross Domestic Product At Current Basic Prices (%) | B2: 2020 | C2: 2021 | D2: 2022 | E2: 2023 | F2: 2024
A4: AGRICULTURE
A5: 1. Crop Production | B5: 14.739473 | C5: 17.187306 | D5: 3.8944914 | E5: =('GDP_Current%'!F5/'GDP_Current%'!E5-1)*100 -> 13.369505 | F5: =('GDP_Current%'!G5/'GDP_Current%'!F5-1)*100 -> 8.8242475
A6: 2. Livestock | B6: 16.446613 | C6: 24.123799 | D6: 22.705829 | E6: =('GDP_Current%'!F6/'GDP_Current%'!E6-1)*100 -> 3.726754 | F6: =('GDP_Current%'!G6/'GDP_Current%'!F6-1)*100 -> 14.614069
A7: 3. Forestry | B7: 9.8071695 | C7: 15.866336 | D7: 24.100502 | E7: =('GDP_Current%'!F7/'GDP_Current%'!E7-1)*100 -> 14.149042 | F7: =('GDP_Current%'!G7/'GDP_Current%'!F7-1)*100 -> 8.7604613
A8: 4. Fishing | B8: 11.776296 | C8: 3.2920252 | D8: 8.2360872 | E8: =('GDP_Current%'!F8/'GDP_Current%'!E8-1)*100 -> 21.8492 | F8: =('GDP_Current%'!G8/'GDP_Current%'!F8-1)*100 -> 22.221922
A9: MINING AND QUARRYING
A10: 5. Crude Petroleum and Natural Gas | B10: -14.69844 | C10: -5.4887069 | D10: 24.25006 | E10: =('GDP_Current%'!F10/'GDP_Current%'!E10-1)*100 -> 9.4664389 | F10: =('GDP_Current%'!G10/'GDP_Current%'!F10-1)*100 -> 11.407574
A11: 6. Coal Mining | B11: -8.782061 | C11: 5.7025614 | D11: 4.8338361 | E11: =('GDP_Current%'!F11/'GDP_Current%'!E11-1)*100 -> 6.7366243 | F11: =('GDP_Current%'!G11/'GDP_Current%'!F11-1)*100 -> -1.0652486
A12: 7. Metal Ores | B12: -64.684139 | C12: 473.75304 | D12: 48.497807 | E12: =('GDP_Current%'!F12/'GDP_Current%'!E12-1)*100 -> 60.096632 | F12: =('GDP_Current%'!G12/'GDP_Current%'!F12-1)*100 -> 94.467714
A13: 8. Quarrying and Other Minerals | B13: 12.58251 | C13: 7.5317157 | D13: 13.084498 | E13: =('GDP_Current%'!F13/'GDP_Current%'!E13-1)*100 -> 9.4325408 | F13: =('GDP_Current%'!G13/'GDP_Current%'!F13-1)*100 -> -19.30117
A14: MANUFACTURING
A15: 9. Oil Refining | B15: -60.294567 | C15: -43.304959 | D15: -37.308711 | E15: =('GDP_Current%'!F15/'GDP_Current%'!E15-1)*100 -> -25.650836 | F15: =('GDP_Current%'!G15/'GDP_Current%'!F15-1)*100 -> -20.030382
A16: 10. Cement | B16: 1.9028907 | C16: 10.733596 | D16: 17.503715 | E16: =('GDP_Current%'!F16/'GDP_Current%'!E16-1)*100 -> 20.965715 | F16: =('GDP_Current%'!G16/'GDP_Current%'!F16-1)*100 -> 17.517529
A17: 11. Food, Beverage and Tobacco | B17: -8.3950957 | C17: 8.7088053 | D17: 13.860481 | E17: =('GDP_Current%'!F17/'GDP_Current%'!E17-1)*100 -> 19.965739 | F17: =('GDP_Current%'!G17/'GDP_Current%'!F17-1)*100 -> 18.351518
A18: 12. Textile, Apparel and Footwear | B18: -9.8830052 | C18: 56.176027 | D18: 19.094105 | E18: =('GDP_Current%'!F18/'GDP_Current%'!E18-1)*100 -> 16.017723 | F18: =('GDP_Current%'!G18/'GDP_Current%'!F18-1)*100 -> -4.1763798
A19: 13. Wood and Wood Products | B19: 3.8873871 | C19: 39.886996 | D19: 28.01274 | E19: =('GDP_Current%'!F19/'GDP_Current%'!E19-1)*100 -> 10.516129 | F19: =('GDP_Current%'!G19/'GDP_Current%'!F19-1)*100 -> 14.586362
A20: 14. Pulp, Paper and Paper Products | B20: -13.683697 | C20: 50.064799 | D20: 2.9550265 | E20: =('GDP_Current%'!F20/'GDP_Current%'!E20-1)*100 -> 10.968818 | F20: =('GDP_Current%'!G20/'GDP_Current%'!F20-1)*100 -> 14.017679
A21: 15. Chemical and Pharmaceutical Products | B21: 16.753858 | C21: 13.833386 | D21: 25.184279 | E21: =('GDP_Current%'!F21/'GDP_Current%'!E21-1)*100 -> 23.05865 | F21: =('GDP_Current%'!G21/'GDP_Current%'!F21-1)*100 -> 21.445035
A22: 16. Non-Metallic Products | B22: -2.6780075 | C22: 15.61383 | D22: 13.988972 | E22: =('GDP_Current%'!F22/'GDP_Current%'!E22-1)*100 -> 10.400226 | F22: =('GDP_Current%'!G22/'GDP_Current%'!F22-1)*100 -> 14.808381
A23: 17. Plastic and Rubber products | B23: -3.8210624 | C23: 11.136719 | D23: 19.797012 | E23: =('GDP_Current%'!F23/'GDP_Current%'!E23-1)*100 -> -10.337952 | F23: =('GDP_Current%'!G23/'GDP_Current%'!F23-1)*100 -> 16.03758
A24: 18. Electrical and Electronics | B24: -2.9228425 | C24: 110.75138 | D24: 32.432361 | E24: =('GDP_Current%'!F24/'GDP_Current%'!E24-1)*100 -> 8.704289 | F24: =('GDP_Current%'!G24/'GDP_Current%'!F24-1)*100 -> 8.251475
A25: 19. Basic metal , Iron and Steel | B25: -4.2423325 | C25: 36.912075 | D25: 4.6141413 | E25: =('GDP_Current%'!F25/'GDP_Current%'!E25-1)*100 -> 11.633098 | F25: =('GDP_Current%'!G25/'GDP_Current%'!F25-1)*100 -> 13.172409
A26: 20. Motor vehicles & assembly | B26: -38.081451 | C26: 80.017756 | D26: 14.184078 | E26: =('GDP_Current%'!F26/'GDP_Current%'!E26-1)*100 -> 14.162097 | F26: =('GDP_Current%'!G26/'GDP_Current%'!F26-1)*100 -> 12.44332
... A32: 26. ACCOMMODATION AND FOOD SERVICES | B32: -6.2114463 | C32: -14.567458 | D32: 21.69279 | E32: =('GDP_Current%'!F32/'GDP_Current%'!E32-1)*100 -> 12.781207 | F32: =('GDP_Current%'!G32/'GDP_Current%'!F32-1)*100 -> 16.346876
A33: TRANSPORTATION AND STORAGE
A34: 27. Road Transport | B34: -42.360119 | C34: 0.03871801 | D34: 5.9627184 | E34: =('GDP_Current%'!F34/'GDP_Current%'!E34-1)*100 -> 12.737176 | F34: =('GDP_Current%'!G34/'GDP_Current%'!F34-1)*100 -> 34.977309
A35: 28. Rail Transport & Pipelines | B35: -0.20432029 | C35: 2.6552997 | D35: 17.083552 | E35: =('GDP_Current%'!F35/'GDP_Current%'!E35-1)*100 -> 16.793577 | F35: =('GDP_Current%'!G35/'GDP_Current%'!F35-1)*100 -> 93.979778
A36: 29. Water Transport | B36: -17.665805 | C36: 7.4723802 | D36: 16.788939 | E36: =('GDP_Current%'!F36/'GDP_Current%'!E36-1)*100 -> 9.6740405 | F36: =('GDP_Current%'!G36/'GDP_Current%'!F36-1)*100 -> 35.392361
A37: 30. Air Transport | B37: -54.535624 | C37: 43.898129 | D37: 22.624023 | E37: =('GDP_Current%'!F37/'GDP_Current%'!E37-1)*100 -> 20.807903 | F37: =('GDP_Current%'!G37/'GDP_Current%'!F37-1)*100 -> 20.121701
A38: 31. Transport Services | B38: -81.342218 | C38: -2.0140365 | D38: 18.621636 | E38: =('GDP_Current%'!F38/'GDP_Current%'!E38-1)*100 -> 19.829201 | F38: =('GDP_Current%'!G38/'GDP_Current%'!F38-1)*100 -> 19.66037
A39: 32. Post and Courier Services | B39: 31.723183 | C39: 82.241647 | D39: 46.280426 | E39: =('GDP_Current%'!F39/'GDP_Current%'!E39-1)*100 -> 34.13286 | F39: =('GDP_Current%'!G39/'GDP_Current%'!F39-1)*100 -> 18.11058
A40: INFORMATION AND COMMUNICATION
A41: 33. Telecommunications | B41: 21.659658 | C41: 11.089107 | D41: 11.252742 | E41: =('GDP_Current%'!F41/'GDP_Current%'!E41-1)*100 -> 10.552343 | F41: =('GDP_Current%'!G41/'GDP_Current%'!F41-1)*100 -> 10.608959
A42: 34. Publishing, | B42: -12.752454 | C42: -0.56555024 | D42: -0.91096001 | E42: =('GDP_Current%'!F42/'GDP_Current%'!E42-1)*100 -> 25.553808 | F42: =('GDP_Current%'!G42/'GDP_Current%'!F42-1)*100 -> 5.3436228
A43: 34. Motion Pictures, Sound recording and Music production | B43: -2.1762899 | C43: 29.76669 | D43: 8.7984487 | E43: =('GDP_Current%'!F43/'GDP_Current%'!E43-1)*100 -> 21.620739 | F43: =('GDP_Current%'!G43/'GDP_Current%'!F43-1)*100 -> 21.390447
A44: 36. Broadcasting | B44: 18.562424 | C44: 2.3597256 | D44: 6.3411485 | E44: =('GDP_Current%'!F44/'GDP_Current%'!E44-1)*100 -> 20.10063 | F44: =('GDP_Current%'!G44/'GDP_Current%'!F44-1)*100 -> 21.022104
A45: 37.ARTS, ENTERTAINMENT AND RECREATION | B45: -26.138503 | C45: 7.0901344 | D45: 28.216472 | E45: =('GDP_Current%'!F45/'GDP_Current%'!E45-1)*100 -> 23.110915 | F45: =('GDP_Current%'!G45/'GDP_Current%'!F45-1)*100 -> 22.196085
A46: FINANCIAL AND INSURANCE
A47: 38. Financial Institutions | B47: 16.913091 | C47: 9.1261343 | D47: 7.8331116 | E47: =('GDP_Current%'!F47/'GDP_Current%'!E47-1)*100 -> 20.895499 | F47: =('GDP_Current%'!G47/'GDP_Current%'!F47-1)*100 -> 22.960208
...

Sheet Real growth rate %
A2: Gross Domestic Product At 2019 Constant Basic Prices (%) | B2: 2020 | C2: 2021 | D2: 2022 | E2: 2023 | F2: 2024
A4: AGRICULTURE
A5: 1. Crop Production | B5: 3.6779608 | C5: 4.1572366 | D5: 2.0773752 | E5: =('GDP_Current%'!F65/'GDP_Current%'!E65-1)*100 -> 3.9639509 | F5: =('GDP_Current%'!G65/'GDP_Current%'!F65-1)*100 -> 2.9131426
A6: 2. Livestock | B6: 0.70908893 | C6: 3.3738717 | D6: 2.7380453 | E6: =('GDP_Current%'!F66/'GDP_Current%'!E66-1)*100 -> -2.9266079 | F6: =('GDP_Current%'!G66/'GDP_Current%'!F66-1)*100 -> -2.1413136
A7: 3. Forestry | B7: 2.2119589 | C7: 3.1796472 | D7: 6.0877237 | E7: =('GDP_Current%'!F67/'GDP_Current%'!E67-1)*100 -> -17.973258 | F7: =('GDP_Current%'!G67/'GDP_Current%'!F67-1)*100 -> 2.5282132
A8: 4. Fishing | B8: -2.6179648 | C8: 0.48243065 | D8: 3.0120278 | E8: =('GDP_Current%'!F68/'GDP_Current%'!E68-1)*100 -> 2.2486789 | F8: =('GDP_Current%'!G68/'GDP_Current%'!F68-1)*100 -> -0.60937181
A9: MINING AND QUARRYING
A10: 5. Crude Petroleum and Natural Gas | B10: -27.989728 | C10: -39.050717 | D10: 24.773129 | E10: =('GDP_Current%'!F70/'GDP_Current%'!E70-1)*100 -> 4.4477429 | F10: =('GDP_Current%'!G70/'GDP_Current%'!F70-1)*100 -> 5.5358763
A11: 6. Coal Mining | B11: -45.612963 | C11: -2.0146355 | D11: -4.1623526 | E11: =('GDP_Current%'!F71/'GDP_Current%'!E71-1)*100 -> -2.5071943 | F11: =('GDP_Current%'!G71/'GDP_Current%'!F71-1)*100 -> -10.586558
A12: 7. Metal Ores | B12: -78.098691 | C12: 430.31064 | D12: 35.32398 | E12: =('GDP_Current%'!F72/'GDP_Current%'!E72-1)*100 -> 45.804872 | F12: =('GDP_Current%'!G72/'GDP_Current%'!F72-1)*100 -> 75.233415
A13: 8. Quarrying and Other Minerals | B13: -28.430323 | C13: -0.79855924 | D13: 2.8412333 | E13: =('GDP_Current%'!F73/'GDP_Current%'!E73-1)*100 -> -9.3163231 | F13: =('GDP_Current%'!G73/'GDP_Current%'!F73-1)*100 -> -26.76894
A14: MANUFACTURING
A15: 9. Oil Refining | B15: -65.800363 | C15: -44.810972 | D15: -39.971191 | E15: =('GDP_Current%'!F75/'GDP_Current%'!E75-1)*100 -> -27.271793 | F15: =('GDP_Current%'!G75/'GDP_Current%'!F75-1)*100 -> -14.667037
A16: 10. Cement | B16: -9.2208596 | C16: 3.1872417 | D16: 7.6851199 | E16: =('GDP_Current%'!F76/'GDP_Current%'!E76-1)*100 -> 1.9483614 | F16: =('GDP_Current%'!G76/'GDP_Current%'!F76-1)*100 -> 2.372784
A17: 11. Food, Beverage and Tobacco | B17: -21.202551 | C17: 0.72921818 | D17: 7.8568276 | E17: =('GDP_Current%'!F77/'GDP_Current%'!E77-1)*100 -> 6.4865863 | F17: =('GDP_Current%'!G77/'GDP_Current%'!F77-1)*100 -> 2.5013049
A18: 12. Textile, Apparel and Footwear | B18: -18.612669 | C18: 10.82327 | D18: 7.5706899 | E18: =('GDP_Current%'!F78/'GDP_Current%'!E78-1)*100 -> 7.1899912 | F18: =('GDP_Current%'!G78/'GDP_Current%'!F78-1)*100 -> -1.5832292
A19: 13. Wood and Wood Products | B19: -2.9274856 | C19: 24.517895 | D19: 12.167894 | E19: =('GDP_Current%'!F79/'GDP_Current%'!E79-1)*100 -> -18.462149 | F19: =('GDP_Current%'!G79/'GDP_Current%'!F79-1)*100 -> 1.9393496
A20: 14. Pulp, Paper and Paper Products | B20: -19.155941 | C20: 33.542922 | D20: -9.811688 | E20: =('GDP_Current%'!F80/'GDP_Current%'!E80-1)*100 -> -8.2920002 | F20: =('GDP_Current%'!G80/'GDP_Current%'!F80-1)*100 -> 0.083595039
A21: 15. Chemical and Pharmaceutical Products | B21: 0.2665063 | C21: 2.2357216 | D21: 10.685248 | E21: =('GDP_Current%'!F81/'GDP_Current%'!E81-1)*100 -> 9.7609728 | F21: =('GDP_Current%'!G81/'GDP_Current%'!F81-1)*100 -> 3.7317817
A22: 16. Non-Metallic Products | B22: -27.478072 | C22: 5.2534015 | D22: 2.2123769 | E22: =('GDP_Current%'!F82/'GDP_Current%'!E82-1)*100 -> -0.91087068 | F22: =('GDP_Current%'!G82/'GDP_Current%'!F82-1)*100 -> 1.963361
A23: 17. Plastic and Rubber products | B23: -10.723285 | C23: 2.3843923 | D23: 1.5712154 | E23: =('GDP_Current%'!F83/'GDP_Current%'!E83-1)*100 -> -15.11691 | F23: =('GDP_Current%'!G83/'GDP_Current%'!F83-1)*100 -> 0.17290708
A24: 18. Electrical and Electronics | B24: -44.692732 | C24: 18.665059 | D24: 25.209123 | E24: =('GDP_Current%'!F84/'GDP_Current%'!E84-1)*100 -> 7.155629 | F24: =('GDP_Current%'!G84/'GDP_Current%'!F84-1)*100 -> 1.2685983
A25: 19. Basic metal , Iron and Steel | B25: -22.099412 | C25: 23.627008 | D25: -6.9896908 | E25: =('GDP_Current%'!F85/'GDP_Current%'!E85-1)*100 -> -7.5470486 | F25: =('GDP_Current%'!G85/'GDP_Current%'!F85-1)*100 -> 0.61553459
A26: 20. Motor vehicles & assembly | B26: -66.718435 | C26: 68.083605 | D26: 5.215868 | E26: =('GDP_Current%'!F86/'GDP_Current%'!E86-1)*100 -> 5.0461432 | F26: =('GDP_Current%'!G86/'GDP_Current%'!F86-1)*100 -> 2.3903344
... A32: 26. ACCOMMODATION AND FOOD SERVICES | B32: -38.313666 | C32: -21.396564 | D32: 8.5641693 | E32: =('GDP_Current%'!F92/'GDP_Current%'!E92-1)*100 -> 4.9798919 | F32: =('GDP_Current%'!G92/'GDP_Current%'!F92-1)*100 -> 3.7167309
A33: TRANSPORTATION AND STORAGE
A34: 27. Road Transport | B34: -51.0582 | C34: -17.599319 | D34: 2.3937528 | E34: =('GDP_Current%'!F94/'GDP_Current%'!E94-1)*100 -> -18.521218 | F34: =('GDP_Current%'!G94/'GDP_Current%'!F94-1)*100 -> 9.8935208
A35: 28. Rail Transport & Pipelines | B35: -10.355842 | C35: -10.932824 | D35: 3.3972224 | E35: =('GDP_Current%'!F95/'GDP_Current%'!E95-1)*100 -> 3.4344503 | F35: =('GDP_Current%'!G95/'GDP_Current%'!F95-1)*100 -> 44.137139
A36: 29. Water Transport | B36: -30.011297 | C36: 5.6901982 | D36: 12.314852 | E36: =('GDP_Current%'!F96/'GDP_Current%'!E96-1)*100 -> 3.4216324 | F36: =('GDP_Current%'!G96/'GDP_Current%'!F96-1)*100 -> 12.578582
A37: 30. Air Transport | B37: -64.679128 | C37: 25.211975 | D37: 14.148462 | E37: =('GDP_Current%'!F97/'GDP_Current%'!E97-1)*100 -> 2.291652 | F37: =('GDP_Current%'!G97/'GDP_Current%'!F97-1)*100 -> -7.9111874
A38: 31. Transport Services | B38: -83.240144 | C38: -14.984097 | D38: 3.4865833 | E38: =('GDP_Current%'!F98/'GDP_Current%'!E98-1)*100 -> 2.7060973 | F38: =('GDP_Current%'!G98/'GDP_Current%'!F98-1)*100 -> 3.5320874
A39: 32. Post and Courier Services | B39: 17.087042 | C39: 58.33804 | D39: 27.764413 | E39: =('GDP_Current%'!F99/'GDP_Current%'!E99-1)*100 -> 15.096285 | F39: =('GDP_Current%'!G99/'GDP_Current%'!F99-1)*100 -> 2.2850234
A40: INFORMATION AND COMMUNICATION
A41: 33. Telecommunications | B41: 8.2662498 | C41: 1.8367686 | D41: 3.6559913 | E41: =('GDP_Current%'!F101/'GDP_Current%'!E101-1)*100 -> 2.1906039 | F41: =('GDP_Current%'!G101/'GDP_Current%'!F101-1)*100 -> 6.2457568
A42: 34. Publishing, | B42: -15.79453 | C42: -13.854647 | D42: -13.726315 | E42: =('GDP_Current%'!F102/'GDP_Current%'!E102-1)*100 -> 21.554013 | F42: =('GDP_Current%'!G102/'GDP_Current%'!F102-1)*100 -> 1.1755329
A43: 34. Motion Pictures, Sound recording and Music production | B43: -4.9796343 | C43: -1.8834659 | D43: 6.4654676 | E43: =('GDP_Current%'!F103/'GDP_Current%'!E103-1)*100 -> 3.8786243 | F43: =('GDP_Current%'!G103/'GDP_Current%'!F103-1)*100 -> 3.0925174
A44: 36. Broadcasting | B44: -10.821967 | C44: -0.052983955 | D44: 4.0608597 | E44: =('GDP_Current%'!F104/'GDP_Current%'!E104-1)*100 -> 6.3604715 | F44: =('GDP_Current%'!G104/'GDP_Current%'!F104-1)*100 -> 2.2119299
A45: 37.ARTS, ENTERTAINMENT AND RECREATION | B45: -28.645201 | C45: -25.961507 | D45: -7.1295869 | E45: =('GDP_Current%'!F105/'GDP_Current%'!E105-1)*100 -> 8.0716677 | F45: =('GDP_Current%'!G105/'GDP_Current%'!F105-1)*100 -> 8.832053
A46: FINANCIAL AND INSURANCE
A47: 38. Financial Institutions | B47: 5.0941757 | C47: 1.6359387 | D47: 2.7065289 | E47: =('GDP_Current%'!F107/'GDP_Current%'!E107-1)*100 -> 2.2861475 | F47: =('GDP_Current%'!G107/'GDP_Current%'!F107-1)*100 -> 2.8889719
...

Sheet Contr_Growth
A1: Gross Domestic Product At 2019 Constant Basic Prices (%)
B2: 2019 | C2: 2020 | D2: 2021 | E2: 2022 | F2: 2023 | G2: 2024
A5: CONTRIBUTION TO GDP
A7: AGRICULTURE | B7: 25.828934 | C7: 28.496776 | D7: 29.296358 | E7: 28.774688 | F7: 28.270959 | G7: 27.808273
A8: INDUSTRIES | B8: 21.080764 | C8: 17.509553 | D8: 15.729374 | E8: 16.609463 | F8: 16.765809 | G8: 16.672167
A9: SERVICES | B9: 53.090303 | C9: 53.993672 | D9: 54.974268 | E9: 54.615849 | F9: 54.963232 | G9: 55.519559
A10: TOTAL | B10: 100 | C10: 100 | D10: 100 | E10: 100 | F10: 100 | G10: 100
A12: NON OIL | B12: 94.150819 | C12: 95.473143 | D12: 97.266755 | E12: 96.730889 | F12: =100-F13 -> 96.686329 | G12: =100-G13 -> 96.617269
A13: OIL | B13: 5.849181 | C13: 4.5268575 | D13: 2.7332452 | E13: 3.2691113 | F13: 3.3136705 | G13: 3.3827313
B14: 100 | C14: 100 | D14: 100 | E14: 100 | F14: 100 | G14: 100
A17: GROWTH | C17: 2020 | D17: 2021 | E17: 2022 | F17: 2023 | G17: 2024
A19: AGRICULTURE | C19: 2.6554294 | D19: 3.7778662 | E19: 2.4629701 | F19: 1.2393543 | G19: 1.6893386
A20: INDUSTRIES | C20: -22.717457 | D20: -9.3175536 | E20: 10.157505 | F20: 4.0131806 | G20: 2.8038737
A21: SERVICES | C21: -5.3718513 | D21: 2.7787725 | E21: 3.6404239 | F21: 3.6986299 | G21: 4.4276953
A23: REAL GROWTH RATE AT BASIC PRICE | C23: -6.9550765 | D23: 0.94546937 | E23: 4.320569 | F23: 3.0432262 | G23: 3.3812888
A24: REAL GROWTH RATE AT MARKET PRICE | C24: -6.3688984 | D24: 1.1092525 | E24: 4.3188295 | F24: 3.3268456 | G24: 4.0623641
A25: NON OIL GROWTH RATE | C25: -5.648285 | D25: 2.8418879 | E25: 3.7458417 | F25: 2.9957592 | G25: 3.307446
A26: OIL GROWTH RATE | C26: -27.989728 | D26: -39.050717 | E26: 24.773129 | F26: 4.4477429 | G26: 5.5358763
